<?xml version="1.0" ?>
<robot name="parallel_manipulator_v2">

<material name="silver">
  <color rgba="0.700 0.700 0.700 1.000"/>
</material>

<link name="base_link">
  <inertial>
    <origin xyz="1.629259084781521e-06 -4.365586561478258e-07 -0.1949999999999999" rpy="0 0 0"/>
    <mass value="0.15357950576430882"/>
    <inertia ixx="2.536301546242955e-05" iyy="2.536301546234975e-05" izz="4.816637249537103e-05" ixy="-2.2311041906111956e-20" iyz="-3.9042924912502906e-20" ixz="-6.135694911673338e-20"/>
  </inertial>
  <visual>
    <origin xyz="0 0 0" rpy="0 0 0"/>
    <geometry>
      <mesh filename="meshes/base_link.stl" scale="0.001 0.001 0.001"/>
    </geometry>
    <material name="silver"/>
    <material/>
  </visual>
  <collision>
    <origin xyz="0 0 0" rpy="0 0 0"/>
    <geometry>
      <mesh filename="meshes/base_link.stl" scale="0.001 0.001 0.001"/>
    </geometry>
  </collision>
</link>

<link name="link21">
  <inertial>
    <origin xyz="-0.03324247590388492 -0.0758002087223684 4.898361939060346e-18" rpy="0 0 0"/>
    <mass value="0.45547965177818356"/>
    <inertia ixx="0.0011681570689737106" iyy="0.00016851636729551481" izz="0.001306199417929717" ixy="-0.0002855871231870762" iyz="-3.4743503220991665e-20" ixz="2.206353275084071e-19"/>
  </inertial>
  <visual>
    <origin xyz="0.057865 -0.100227 -0.0" rpy="0 0 0"/>
    <geometry>
      <mesh filename="meshes/link21.stl" scale="0.001 0.001 0.001"/>
    </geometry>
    <material name="silver"/>
    <material/>
  </visual>
  <collision>
    <origin xyz="0.057865 -0.100227 -0.0" rpy="0 0 0"/>
    <geometry>
      <mesh filename="meshes/link21.stl" scale="0.001 0.001 0.001"/>
    </geometry>
  </collision>
</link>

<link name="link11">
  <inertial>
    <origin xyz="-0.04902409142648638 0.06668874911040017 0.0" rpy="0 0 0"/>
    <mass value="0.45547965177818334"/>
    <inertia ixx="0.0006657522463887869" iyy="0.0006709211898804374" izz="0.001306199417929716" ixy="0.000575650682748645" iyz="-4.908429218630772e-19" ixz="0.0"/>
  </inertial>
  <visual>
    <origin xyz="-0.115734 0.0 -0.0" rpy="0 0 0"/>
    <geometry>
      <mesh filename="meshes/link11.stl" scale="0.001 0.001 0.001"/>
    </geometry>
    <material name="silver"/>
    <material/>
  </visual>
  <collision>
    <origin xyz="-0.115734 0.0 -0.0" rpy="0 0 0"/>
    <geometry>
      <mesh filename="meshes/link11.stl" scale="0.001 0.001 0.001"/>
    </geometry>
  </collision>
</link>

<link name="link51">
  <inertial>
    <origin xyz="0.08215721093458689 -4.3655865613396777e-07 0.06952242193395955" rpy="0 0 0"/>
    <mass value="1.0150113529400209"/>
    <inertia ixx="0.0029729990597885288" iyy="0.004766557329442454" izz="0.0019058159288479707" ixy="3.714239473710107e-19" iyz="-3.15552860076729e-19" ixz="-0.0020157152695402403"/>
  </inertial>
  <visual>
    <origin xyz="-2e-06 0.0 0.17" rpy="0 0 0"/>
    <geometry>
      <mesh filename="meshes/link51.stl" scale="0.001 0.001 0.001"/>
    </geometry>
    <material name="silver"/>
    <material/>
  </visual>
  <collision>
    <origin xyz="-2e-06 0.0 0.17" rpy="0 0 0"/>
    <geometry>
      <mesh filename="meshes/link51.stl" scale="0.001 0.001 0.001"/>
    </geometry>
  </collision>
</link>

<link name="link41">
  <inertial>
    <origin xyz="-0.04017439988018685 -0.06958389617262824 0.06008552157712839" rpy="0 0 0"/>
    <mass value="0.9508914468802544"/>
    <inertia ixx="0.003442287452174054" iyy="0.0025807418276347534" izz="0.0018281247321898916" ixy="-0.0007461203973703019" iyz="0.001445333763697901" ixz="0.0008344638375399512"/>
  </inertial>
  <visual>
    <origin xyz="-2e-06 0.0 0.15" rpy="0 0 0"/>
    <geometry>
      <mesh filename="meshes/link41.stl" scale="0.001 0.001 0.001"/>
    </geometry>
    <material name="silver"/>
    <material/>
  </visual>
  <collision>
    <origin xyz="-2e-06 0.0 0.15" rpy="0 0 0"/>
    <geometry>
      <mesh filename="meshes/link41.stl" scale="0.001 0.001 0.001"/>
    </geometry>
  </collision>
</link>

<link name="link61">
  <inertial>
    <origin xyz="-0.04187640487355906 0.07253098217857246 0.0792058878295866" rpy="0 0 0"/>
    <mass value="1.079131258999788"/>
    <inertia ixx="0.00536124096481776" iyy="0.004432156892161487" izz="0.001977649980589322" ixy="0.0008046104091717857" iyz="-0.00206211986239419" ixz="0.0011905654576544536"/>
  </inertial>
  <visual>
    <origin xyz="-2e-06 0.0 0.19" rpy="0 0 0"/>
    <geometry>
      <mesh filename="meshes/link61.stl" scale="0.001 0.001 0.001"/>
    </geometry>
    <material name="silver"/>
    <material/>
  </visual>
  <collision>
    <origin xyz="-2e-06 0.0 0.19" rpy="0 0 0"/>
    <geometry>
      <mesh filename="meshes/link61.stl" scale="0.001 0.001 0.001"/>
    </geometry>
  </collision>
</link>

<link name="ring1">
  <inertial>
    <origin xyz="2.520472576825055e-07 -0.10000043655865562 -7.274033520878354e-17" rpy="0 0 0"/>
    <mass value="1.3495756390295186"/>
    <inertia ixx="0.005053549887178739" iyy="0.005053549887178443" izz="0.010016882541278834" ixy="-2.71302269538689e-17" iyz="8.924416761146806e-18" ixz="-3.8949917152420185e-33"/>
  </inertial>
  <visual>
    <origin xyz="-0.0 -0.1 -0.0" rpy="0 0 0"/>
    <geometry>
      <mesh filename="meshes/ring1.stl" scale="0.001 0.001 0.001"/>
    </geometry>
    <material name="silver"/>
    <material/>
  </visual>
  <collision>
    <origin xyz="-0.0 -0.1 -0.0" rpy="0 0 0"/>
    <geometry>
      <mesh filename="meshes/ring1.stl" scale="0.001 0.001 0.001"/>
    </geometry>
  </collision>
</link>

<link name="link31">
  <inertial>
    <origin xyz="-0.06220304726877052 -0.04111728662265633 0.0" rpy="0 0 0"/>
    <mass value="0.4554796517781839"/>
    <inertia ixx="0.00017110083904134247" iyy="0.0011655725972278847" izz="0.0013061994179297187" ixy="-0.0002900635595615679" iyz="0.0" ixz="0.0"/>
  </inertial>
  <visual>
    <origin xyz="-0.086603 0.05 -0.0" rpy="0 0 0"/>
    <geometry>
      <mesh filename="meshes/link31.stl" scale="0.001 0.001 0.001"/>
    </geometry>
    <material name="silver"/>
    <material/>
  </visual>
  <collision>
    <origin xyz="-0.086603 0.05 -0.0" rpy="0 0 0"/>
    <geometry>
      <mesh filename="meshes/link31.stl" scale="0.001 0.001 0.001"/>
    </geometry>
  </collision>
</link>

<joint name="Revolute_3" type="continuous">
  <origin xyz="-0.057867 0.100227 0.19" rpy="0 0 0"/>
  <parent link="link61"/>
  <child link="link21"/>
  <axis xyz="0.5 -0.866025 0.0"/>
</joint>
<transmission name="Revolute_3_tran">
  <type>transmission_interface/SimpleTransmission</type>
  <joint name="Revolute_3">
    <hardwareInterface>PositionJointInterface</hardwareInterface>
  </joint>
  <actuator name="Revolute_3_actr">
    <hardwareInterface>PositionJointInterface</hardwareInterface>
    <mechanicalReduction>1</mechanicalReduction>
  </actuator>
</transmission>

<joint name="Revolute_4" type="continuous">
  <origin xyz="0.115732 0.0 0.17" rpy="0 0 0"/>
  <parent link="link51"/>
  <child link="link11"/>
  <axis xyz="-1.0 0.0 0.0"/>
</joint>
<transmission name="Revolute_4_tran">
  <type>transmission_interface/SimpleTransmission</type>
  <joint name="Revolute_4">
    <hardwareInterface>PositionJointInterface</hardwareInterface>
  </joint>
  <actuator name="Revolute_4_actr">
    <hardwareInterface>PositionJointInterface</hardwareInterface>
    <mechanicalReduction>1</mechanicalReduction>
  </actuator>
</transmission>

<joint name="Revolute_8" type="continuous">
  <origin xyz="0.0 0.0 0.02" rpy="0 0 0"/>
  <parent link="link61"/>
  <child link="link51"/>
  <axis xyz="0.0 0.0 -1.0"/>
</joint>
<transmission name="Revolute_8_tran">
  <type>transmission_interface/SimpleTransmission</type>
  <joint name="Revolute_8">
    <hardwareInterface>PositionJointInterface</hardwareInterface>
  </joint>
  <actuator name="Revolute_8_actr">
    <hardwareInterface>PositionJointInterface</hardwareInterface>
    <mechanicalReduction>1</mechanicalReduction>
  </actuator>
</transmission>

<joint name="Revolute_9" type="continuous">
  <origin xyz="0.0 0.0 0.02" rpy="0 0 0"/>
  <parent link="link51"/>
  <child link="link41"/>
  <axis xyz="0.0 0.0 -1.0"/>
</joint>
<transmission name="Revolute_9_tran">
  <type>transmission_interface/SimpleTransmission</type>
  <joint name="Revolute_9">
    <hardwareInterface>PositionJointInterface</hardwareInterface>
  </joint>
  <actuator name="Revolute_9_actr">
    <hardwareInterface>PositionJointInterface</hardwareInterface>
    <mechanicalReduction>1</mechanicalReduction>
  </actuator>
</transmission>

<joint name="Rigid_10" type="fixed">
  <origin xyz="2e-06 0.0 -0.19" rpy="0 0 0"/>
  <parent link="base_link"/>
  <child link="link61"/>
</joint>

<joint name="Revolute_12" type="continuous">
  <origin xyz="-0.115734 0.1 0.0" rpy="0 0 0"/>
  <parent link="link11"/>
  <child link="ring1"/>
  <axis xyz="0.0 1.0 0.0"/>
</joint>
<transmission name="Revolute_12_tran">
  <type>transmission_interface/SimpleTransmission</type>
  <joint name="Revolute_12">
    <hardwareInterface>PositionJointInterface</hardwareInterface>
  </joint>
  <actuator name="Revolute_12_actr">
    <hardwareInterface>PositionJointInterface</hardwareInterface>
    <mechanicalReduction>1</mechanicalReduction>
  </actuator>
</transmission>

<joint name="Revolute_13" type="continuous">
  <origin xyz="0.086603 -0.15 0.0" rpy="0 0 0"/>
  <parent link="ring1"/>
  <child link="link31"/>
  <axis xyz="-0.866025 0.5 0.0"/>
</joint>
<transmission name="Revolute_13_tran">
  <type>transmission_interface/SimpleTransmission</type>
  <joint name="Revolute_13">
    <hardwareInterface>PositionJointInterface</hardwareInterface>
  </joint>
  <actuator name="Revolute_13_actr">
    <hardwareInterface>PositionJointInterface</hardwareInterface>
    <mechanicalReduction>1</mechanicalReduction>
  </actuator>
</transmission>

</robot>
