<mujoco model="joint example">
    <worldbody>
        <light pos="0 0 1"/>
        <geom type="plane" size="1 1 0.1" rgba="0 .9 0 1"/>

        <!-- <body name="weight" pos="-.03 0 .175"> -->
        <body>
            <joint axis="0 0 1" pos="0 0 .025" type="slide"/>
            <geom type="cylinder" size=".03 .025" density="5000" pos="0.3 0 -0.3" rgba=".2 .2 .5 1"/>
            <!-- <site name="s1" pos="0 0 .025"/> -->
        </body>
        <!-- <body>3
            <joint type="free" pos="1.0 1.0 .025">
            <geom type="box" size="0.2 0.15 0.1" pos="0 0 .025"/>
            <geom type="box" size="0.1 0.1 0.1" pos="0.1 0.1 .025"/>
        </body> -->
    </worldbody>

</mujoco>