<mujoco>
    <option timestep="0.0001"/>
    <option gravity="0 0 -9.81"/>
    <worldbody>
        <geom type="plane" size="10 10 0.1" pos="0 0 -5" rgba="1 0 0 1"/>
        <light diffuse="0.7 0.7 0.7" pos="0 0 3"/>
        <body name="torso" pos="0.2 0.25 0">
            <geom type="box" pos="0 0.35 0" size="0.15 0.25 0.27" rgba="0.5 0.5 0.5 1"/>
            <geom type="box" pos="0 0.35 -0.5" size="0.15 0.33 0.3" rgba="0.5 0.5 0.5 1"/>
            <body name="arm" pos="0 0 0">
                <joint name="shoulder1" pos="0 0 0" axis="0 1 0" range="0 180"/>
                <geom type="cylinder" size="0.1 0.1" pos="0 0 0" rgba="0.1 0.1 0.1 1" euler="90 0 0" mass="0.06"/>
                <body name="torse_part2" pos="0 -0.2 0">
                    <joint name="shoulder2" pos="0 0 0" axis="0 0 1" range="-2 2"/>
                    <geom type="cylinder" size="0.1 0.1" pos="0 0 0" rgba="0.1 0.1 0.1 1" mass="0.06"/>
                    <body name="body3" pos="0.2 0 0">
                        <geom type="cylinder" size="0.1 0.1" pos="0 0 0" rgba="0.1 0.1 0.1 1" euler="0 90 0" mass="0.06"/>
                        <body name="elbow" pos="0.45 0 0">
                            <geom type="box" size="0.5 0.025 0.1" pos="0 -0.125 0" rgba="0 0.8 0.2 1" mass="0.02"/>
                            <geom type="box" size="0.5 0.025 0.1" pos="0 0.125 0" rgba="0 0.8 0.2 1" mass="0.02"/>
                            <body pos="0 0 0">
                                <joint pos="0.5 0 0" axis="0 1 0" range="-90 0"/>
                                <geom type="cylinder" size="0.1 0.1" pos="0.5 0 0" euler="90 0 0" rgba="0.1 0.1 0.1 1" mass="0.06"/>
                                <body>
                                    <geom type="box" size="0.5 0.08 0.1" pos="0.95 0 0" rgba="1 0 1 1" mass="0.02"/>
                                    <body name="wrist" pos="1.5 0 0">
                                        <geom type="sphere" size="0.15" pos="0 0 0" rgba="1 0.7 0.6 1"/>
                                    </body>
                                </body>
                            </body>
                        </body>
                    </body>
                </body>
            </body>
        </body>
    </worldbody>
</mujoco>